# 摘自：通义千问2024-12-30
# 问：异常的异常        



######################################################################################
# 答：
    # 你提到的“异常的异常”可能指的是在处理一个异常的过程中，又抛出了另一个异常。这种情况在 Python 中是完全合法的，
    # 但可能会导致一些复杂的行为，尤其是在调试和维护代码时。让我们详细探讨一下这种情况下会发生什么，以及如何处理这种情况。


######################################################################################
# 1. 什么是“异常的异常”？
    # “异常的异常”通常指的是在 try-except 块中捕获一个异常时，except 块中的代码本身又抛出了另一个异常。
    # 换句话说，在处理第一个异常的过程中，第二个异常发生了。这可能会导致以下几种情况：
        # 第一个异常被覆盖：如果在 except 块中抛出了一个新的异常，Python 会用新的异常替换原来的异常。这意味着原始异常的信息可能会丢失，
        # 调试时可能会难以追踪问题的根源。
        # 多个异常同时存在：从 Python 3.11 开始，Python 引入了对“异常组”的支持（通过 PEP 654），允许你同时捕获和处理多个异常。
        # 然而，在较早的 Python 版本中，一次只能有一个活跃的异常。



######################################################################################
# 2. 示例：异常的异常
    # 下面是一个简单的例子，展示了在处理一个异常时，except 块中又抛出了另一个异常：


def divide(a, b):
    try:
        return a / b
    except ZeroDivisionError as e:
        print(f"Caught ZeroDivisionError: {e}")
        raise ValueError("Cannot divide by zero")  # 抛出新的异常

def test_divide():
    try:
        result = divide(10, 0)
        print(f"Result: {result}")
    except ValueError as e:
        print(f"Caught ValueError: {e}")

test_divide()


# 输出：
    # Caught ZeroDivisionError: division by zero
    # Caught ValueError: Cannot divide by zero

# 在这个例子中：
    # divide(10, 0) 抛出了 ZeroDivisionError。
    # 在 except ZeroDivisionError 块中，我们捕获了 ZeroDivisionError 并打印了相关信息。
    # 然后我们在 except 块中又抛出了一个新的 ValueError。
    # 最终，test_divide() 捕获了 ValueError 并打印了相应的信息。

# 注意：
    # 原始异常被覆盖：ZeroDivisionError 被捕获并处理后，ValueError 成为了当前的活跃异常。
    # ZeroDivisionError 的信息不再直接可见，除非你在 except 块中显式地保存或记录它。



######################################################################################

# 3. 如何避免异常的异常？
    # 为了避免在处理一个异常时又抛出另一个异常，或者至少确保原始异常的信息不会丢失，你可以采取以下几种策略：

# 3.1 使用 raise from 语句
    # 从 Python 3.3 开始，引入了 raise from 语句，允许你在抛出新异常时显式地将原始异常作为上下文关联起来。
    # 这样可以在调试时保留原始异常的信息。

print("\n\n#####################################################################")
def divide(a, b):
    try:
        return a / b
    except ZeroDivisionError as e:
        print(f"Caught ZeroDivisionError: {e}")
        raise ValueError("Cannot divide by zero") from e  # 使用 raise from 关联原始异常

def test_divide():
    try:
        result = divide(10, 0)
        print(f"Result: {result}")
    except ValueError as e:
        print(f"Caught ValueError: {e}")
        print(f"Original exception: {e.__cause__}")  # 访问原始异常

test_divide()

# 输出：
    # Caught ZeroDivisionError: division by zero
    # Caught ValueError: Cannot divide by zero
    # Original exception: division by zero

# 解释：
    # raise ValueError(...) from e 将 ZeroDivisionError 作为 ValueError 的原因（即上下文）关联起来。
    # 在捕获 ValueError 时，你可以通过 e.__cause__ 访问原始的 ZeroDivisionError，从而保留了完整的异常链。



# 3.2 记录原始异常
    # 如果你不想抛出新的异常，而是想继续执行代码，可以将原始异常的信息记录下来，例如通过日志记录或将其存储在变量中。


print("\n\n#####################################################################")
import logging

def divide(a, b):
    try:
        return a / b
    except ZeroDivisionError as e:
        logging.error(f"Caught ZeroDivisionError: {e}")
        return None  # 返回 None 或其他默认值，而不是抛出新异常

def test_divide():
    result = divide(10, 0)
    if result is None:
        print("Division failed, using default value.")
    else:
        print(f"Result: {result}")

test_divide()

# 输出：
    # ERROR:root:Caught ZeroDivisionError: division by zero
    # Division failed, using default value.
# 解释：
    # 在 except 块中，我们使用 logging.error 记录了 ZeroDivisionError 的信息，并返回 None 作为结果。
    # 这样可以避免抛出新的异常，程序将继续执行后续代码。



# 3.3 使用 contextlib.suppress
    # 如果你只是想忽略某些特定类型的异常，并且不希望它们影响程序的正常执行，可以使用 contextlib.suppress，正如我们之前讨论过的。

print("\n\n#####################################################################")
from contextlib import suppress

def divide(a, b):
    with suppress(ZeroDivisionError):
        return a / b
    return None  # 如果发生 ZeroDivisionError，返回 None

def test_divide():
    result = divide(10, 0)
    if result is None:
        print("Division failed, using default value.")
    else:
        print(f"Result: {result}")

test_divide()

# 输出：
    # Division failed, using default value.

# 解释：
    # with suppress(ZeroDivisionError) 捕获并忽略 ZeroDivisionError，程序将继续执行后续代码。




######################################################################################
# 4. 异常链的调试
    # 在调试复杂的异常链时，Python 提供了一些工具来帮助你查看异常的完整历史。你可以使用 traceback 模块来获取更详细的异常信息，
    # 或者使用 raise from 语句来保留异常链。

# 4.1 使用 traceback 模块
    # traceback 模块可以帮助你获取更详细的异常堆栈信息，包括所有相关的异常链。

print("\n\n#####################################################################")
import traceback

def divide(a, b):
    try:
        return a/b
    except ZeroDivisionError as e:
        print(f"Caught ZeroDivisionError: {e}")
        raise ValueError("Cannot divide by zero") from e

def test_divide():
    try:
        result = divide(10, 0)
        print(f"Result: {result}")
    except ValueError as e:
        print(f"Caught ValueError: {e}")
        print("Full traceback:")
        traceback.print_exc()

test_divide()

print("\n\n以上代码全部执行成功#####################################################################")


# 输出：
    # Caught ZeroDivisionError: division by zero
    # Caught ValueError: Cannot divide by zero
    # Full traceback:
    # Traceback (most recent call last):
    #   File "example.py", line 17, in test_divide
    #     result = divide(10, 0)
    #   File "example.py", line 7, in divide
    #     return a / b
    # ZeroDivisionError: division by zero

    # The above exception was the direct cause of the following exception:

    # Traceback (most recent call last):
    #   File "example.py", line 19, in test_divide
    #     raise ValueError("Cannot divide by zero") from e
    # ValueError: Cannot divide by zero

# 解释：
    # traceback.print_exc() 打印了完整的异常链，包括 ZeroDivisionError 和 ValueError 的堆栈跟踪信息。
    # 这有助于你更好地理解异常的发生顺序和原因。




# 5. 总结
    # “异常的异常” 是指在处理一个异常的过程中，except 块中的代码又抛出了另一个异常。这种情况会导致原始异常被覆盖，或者形成复杂的异常链。
    # 使用 raise from 语句 可以保留原始异常的信息，形成明确的异常链，便于调试和维护。
    # 记录原始异常 或者 忽略某些异常 也可以避免不必要的异常抛出，确保程序继续执行。
    # 使用 traceback 模块 可以帮助你获取更详细的异常堆栈信息，方便调试复杂的异常链。